Workbook
Name Slicer_City_Name: #N/A
Name Slicer_Current_Status__Live_Not_Live: #N/A
Name Slicer_Remarks_Grouped: #N/A
Name Slicer_Status: #N/A
Name Slicer_Std_Remarks: #N/A
Name Slicer_Timeline___Monthwise: #N/A

Sheet Area Wise Spread - DB 2
A1: Number of CEMs | B1: =COUNT(B4:B98) -> 95
A3: Row Labels | B3: Sum of Total H.P | C3: Sum of Customers According to % (Market Share) | D3: Sum of HP Based on completion - Realistic
A4: Abbottabad | B4: 1864 | C4: 745.6 | D4: 745.6
A5: Gulfam Town_Mera Muzzafar | B5: 450 | C5: 180 | D5: 180
A6: Malikpura | B6: 714 | C6: 285.6 | D6: 285.6
A7: Salhad | B7: 700 | C7: 280 | D7: 280
A8: Abbottabad Ph2 | B8: 1826 | C8: 730.4 | D8: 730.4
A9: Al Mansoor Town Ext. | B9: 440 | C9: 176 | D9: 176
A10: Jhangi Qazian | B10: 420 | C10: 168 | D10: 168
A11: Jhangi Saeedan Extension | B11: 482 | C11: 192.8 | D11: 192.8
A12: Kaghan Colony Extension | B12: 302 | C12: 120.8 | D12: 120.8
A13: Kareenpura Extension | B13: 182 | C13: 72.8 | D13: 72.8
A14: Al Hafeez Garden & Tariq Garden | B14: 5502 | C14: 2200.8
A15: Al Hafeez Garden Ph-5 | B15: 1450 | C15: 580
A16: Al Hafeez Gdn Ph-2 | B16: 1404 | C16: 561.6
A17: Al Raheem Gdn Ph-2 Extn. | B17: 1150 | C17: 460
A18: Tariq Garden | B18: 1498 | C18: 599.2
A19: Al Jalil & Al khalil LHE | B19: 17546 | C19: 7018.4 | D19: 7018.4
A20: Al Hamra | B20: 424 | C20: 169.6 | D20: 169.6
A21: Al Jalil Housing P2 | B21: 2232 | C21: 892.8 | D21: 892.8
A22: Al Jalil Housing P3 | B22: 2210 | C22: 884 | D22: 884
A23: Al Jalil Housing P4 | B23: 2106 | C23: 842.4 | D23: 842.4
A24: Al Kabeer Ph-2-Pk1 | B24: 2268 | C24: 907.2 | D24: 907.2
A25: Al Kabeer Ph-2-Pk2 | B25: 3086 | C25: 1234.4 | D25: 1234.4
A26: Al Kabeer Ph-2-Pk3 | B26: 776 | C26: 310.4 | D26: 310.4
A27: Al Kabeer Town Ph-1 | B27: 512 | C27: 204.8 | D27: 204.8
A28: Central Park Housing-P1 | B28: 1526 | C28: 610.4 | D28: 610.4
A29: Central Park Housing-P2 | B29: 1200 | C29: 480 | D29: 480
A30: Central Park Housing-P3 | B30: 1206 | C30: 482.4 | D30: 482.4
... A138: Gulshan e Ali | B138: 934 | C138: 373.6 | D138: 373.6
A139: Darussalam_LucknowSociety_DadabhoyTown | B139: 3058 | C139: 1223.2
A140: Darussalam Society | B140: 1074 | C140: 429.6
A141: Lucknow Society | B141: 1322 | C141: 528.8
A142: Dadabhoy Town | B142: 662 | C142: 264.8
A143: Daska | B143: 21078 | C143: 8431.2 | D143: 8431.2
A144: Barkat Town | B144: 592 | C144: 236.8 | D144: 236.8
A145: Bhatti Colony | B145: 536 | C145: 214.4 | D145: 214.4
A146: Civil Lines | B146: 598 | C146: 239.2 | D146: 239.2
A147: Faisal_Town | B147: 320 | C147: 128 | D147: 128
A148: Garden Town | B148: 1288 | C148: 515.2 | D148: 515.2
...

Sheet Arial, Hybrid, Buried
A1: Number of Total Areas | B1: =COUNTA(B4:B1025) -> 4
A3: Row Labels | B3: Count of Area / Section / Pocket / Society (Original Name)
A4: Arial | B4: 93
A5: Buried | B5: 253
A6: Hybrid | B6: 804
A7: Grand Total | B7: 1150

Sheet HP - Customer Network
A1: Home Passes - Total | B1: =SUBTOTAL(9,B4:B245)/2 -> 1444140 | C1: =SUBTOTAL(9,C4:C245)/2 -> 600881.5 | D1: =SUBTOTAL(9,D4:D245)/2 -> 544448.26 | E1: =SUBTOTAL(9,E4:E245)/2 -> 229830.1 | F1: =SUBTOTAL(9,F4:F245)/2 -> 557486
A3: Row Labels | B3: Sum of Total H.P | C3: Sum of Customers According to % (Market Share) | D3: Sum of HP Based on completion - Realistic | E3: Sum of Sellable Capacity - E | F3: Sum of Sellable Capacity - T
A4: Abbottabad | B4: 3690 | C4: 1476 | D4: 1476 | E4: 1196 | F4: 2990
A5: Bahawalpur | B5: 28960 | C5: 11632.6 | D5: 11632.6 | E5: 3274.2 | F5: 8064
A6: Chitral | B6: 3832 | C6: 1532.8 | D6: 909.2 | E6: 623.6 | F6: 3118
A7: Daska | B7: 21078 | C7: 8431.2 | D7: 8431.2 | E7: 381.6 | F7: 954
A8: Dera Ghazi Khan | B8: 23218 | C8: 10448.1 | D8: 10448.1 | E8: 0 | F8: 0
A9: Faisalabad | B9: 37542 | C9: 16203.2 | D9: 14216 | E9: 13719.2 | F9: 32988
A10: Gujranwala | B10: 144722 | C10: 57941.6 | D10: 52338.4 | E10: 36427.2 | F10: 91068
A11: Hafizabad | B11: 27226 | C11: 12251.7 | D11: 12251.7 | E11: 0 | F11: 0
A12: Haripur | B12: 9672 | C12: 3868.8 | D12: 3868.8 | E12: 3212.8 | F12: 8032
A13: Hyderabad | B13: 17942 | C13: 7176.8 | D13: 6623.16 | E13: 4163.96 | F13: 11054
A14: Islamabad | B14: 103742 | C14: 44256.4 | D14: 43688.08 | E14: 26058.28 | F14: 60594
A15: Jhang | B15: 17360 | C15: 7812 | D15: 7812 | E15: 0 | F15: 0
... A36: Wahh | B36: 10504 | C36: 4716.8 | D36: 4716.8 | E36: 539.2 | F36: 1348
A37: Sukkur | B37: 18858 | C37: 7543.2 | E37: 0 | F37: 0
A38: Grand Total | B38: 1444140 | C38: 600881.5 | D38: 544448.26 | E38: 229830.1 | F38: 557486

Sheet Budgets
A1: Number of Total Areas | B1: =SUBTOTAL(9,B4:B201)/2 -> 1.8581034e+10 | C1: =SUBTOTAL(9,C4:C201)/2 -> 8.480651e+09 | D1: =SUBTOTAL(9,D4:D201)/2 -> 9.5197204e+09
A3: Row Labels | B3: Sum of Allocated Budget | C3: Sum of Revised Budget | D3: Sum of Difference
A4: Abbottabad | B4: 46635361 | C4: 4933262.7 | D4: 41702098
A5: Bahawalpur | B5: 2.3472034e+08 | C5: 78068027 | D5: 48751767
A6: Chitral | B6: 1.0745748e+08 | C6: 69955211 | D6: 37502271
A7: Daska | B7: 2.3819094e+08 | C7: 1.5004045e+08 | D7: 88150495
A8: Dera Ghazi Khan | B8: 4.1567031e+08 | C8: 4.1567031e+08
A9: Faisalabad | B9: 7.1513106e+08 | C9: 91398554 | D9: 5.6781073e+08
A10: Gujranwala | B10: 1.6429799e+09 | C10: 5.917392e+08 | D10: 1.0158168e+09
A11: Hafizabad | B11: 2.525768e+08 | C11: 2.525768e+08
A12: Haripur | B12: 1.661863e+08 | C12: 37229960 | D12: 1.2895634e+08
A13: Hyderabad | B13: 2.4718492e+08 | C13: 62007416 | D13: 1.7899249e+08
A14: Islamabad | B14: 1.8992789e+09 | C14: 8.5374564e+08 | D14: 1.0404171e+09
A15: Jhang | B15: 1.9091471e+08 | C15: 1.9091471e+08
A16: Jhelum | B16: 1.7292679e+08 | C16: 71668193 | D16: 51090933
A17: Karachi | B17: 2.1482582e+09 | C17: 9.1201307e+08 | D17: 1.1443347e+09
A18: Kasur | B18: 2.7718237e+08 | C18: 2.762782e+08
A19: Lahore | B19: 4.6871497e+09 | C19: 2.1832791e+09 | D19: 2.378936e+09
A20: Lalamusa | B20: 1.5178954e+08 | C20: 1.5178954e+08
A21: Mandi Bahauddin | B21: 3.0304575e+08 | C21: 3.0304575e+08
A22: Mardan | B22: 1.9876333e+08 | C22: 27323022 | D22: 1.714403e+08
A23: Multan | B23: 1.2777487e+09 | C23: 4.440241e+08 | D23: 8.0609967e+08
A24: Narowal | B24: 2.7474469e+08 | C24: 2.7474469e+08
A25: Okara | B25: 1.024588e+08 | C25: 15368820 | D25: 87089979
A26: Peshawar | B26: 3.0707597e+08 | C26: 99622300 | D26: 2.0745367e+08
A27: Quetta | B27: 1.3533896e+08 | C27: 22356218 | D27: 1.1298274e+08
A28: Rahim Yar Khan | B28: 1.1107145e+08 | C28: 14964640 | D28: 96106805
A29: Rawalpindi | B29: 1.7727756e+08 | C29: 47104579 | D29: 1.3017298e+08
A30: Sadiqabad | B30: 3.5043392e+08 | C30: 3.5043392e+08
A31: Sahiwal | B31: 85781337 | C31: 42199240 | D31: 39901742
A32: Sargodha | B32: 1.9330305e+08 | C32: 50749454 | D32: 1.425536e+08
A33: Sialkot | B33: 4.8328493e+08 | C33: 1.4187399e+08 | D33: 3.4141093e+08
A34: Swat | B34: 4.659263e+08 | C34: 93712460 | D34: 3.6429266e+08
A35: Torkhan Border | B35: 125214350 | C35: 18782152 | D35: 1.064322e+08
A36: Wahh | B36: 2.1079129e+08 | C36: 19469859 | D36: 1.9132143e+08
A37: Sukkur | B37: 1.8454016e+08 | C37: 1.2156825e+08
A38: Grand Total | B38: 1.8581034e+10 | C38: 8.480651e+09 | D38: 9.5197204e+09

Sheet Timeline Box
A1: Number of Total Areas | B1: =COUNTA(B4:B1025) -> 9
A3: Row Labels | B3: Count of CEM Number | F3: m | G3: C
A4: Apr-2026 | B4: 61 | F4: 46113 | G4: 61
A5: Feedback Awaited | B5: 45 | F5: 46204 | G5: 33
A6: Jul-2026 | B6: 33 | F6: 46174 | G6: 64
A7: Jun-2026 | B7: 64 | F7: 46082 | G7: 37
A8: Mar-2026 | B8: 37 | F8: 46143 | G8: 26
A9: May-2026 | B9: 26 | F9: 46296 | G9: 292
A10: Oct-2026 | B10: 292
A11: Timeline not applicable | B11: 592
A12: Grand Total | B12: 1150

Sheet Table of Contents
B2: Table of Content
B6: Dashboard - Summary
B7: Dashboard - Feasibility
B8: Dashboard - Financials
B9: Data Bank
B10: Timeline Box
B11: Standardized Comments
B12: HP - Customer Network
B13: Arial, Buried, Hybrid
B14: City Names
B15: Budgets
B16: Swap Details
... B20: Live/Not Live

Sheet Data Bank
P1: Feeder | Q1: 0.5 | R1: 1
P2: 100% Live | Q2: 0.15 | S2: 7805702.2 | T2: =S2*0.15 -> 1170855.3
T3: =S2*0.3*0.85 -> 1990454.1
F5: =SUBTOTAL(9,F8:F1380) -> 1444140 | G5: =SUBTOTAL(9,G8:G1380) -> 600881.5 | P5: =SUBTOTAL(9,Table8[Allocated Budget]) -> 2.209571e+10 | Q5: =SUBTOTAL(9,Table8[Revised Budget]) -> 1.0815617e+10 | V5: =SUBTOTAL(9,Table8[Total Civil works - Buried]) -> 7192974.7 | W5: =SUBTOTAL(9,Table8[Total Civil works - Arial]) -> #REF! | AQ5: =AQ520+AQ528+AQ773+AQ775+AQ780+AQ781+AQ793+AQ810+AQ811+AQ822+AQ1256 -> 0 | BP5: ßßßßßßß
Q6: =Q5/P5 -> 0.48948946 | AF6: AZ
A7: CEM Number | B7: CEM Initiation Date | C7: City Name | D7: Fesibility Name | E7: Area / Section / Pocket / Society (Original Name) | F7: Total H.P | G7: Customers According to % (Market Share) | H7: New Customers | I7: Terminated | J7: Active | K7: Not Active | L7: Remarks - Actuals | M7: Customers based on completion | N7: HP% based on Live % ( Work Progress) | O7: HP Based on completion - Realistic | P7: Allocated Budget | Q7: Revised Budget | R7: Difference | S7: Costing Efficiency | T7: Area / Section / Pocket / Society (Revised Name) | U7: Customers Take up %age (Key Factor) | V7: Total Civil works - Buried | W7: Total Civil works - Arial | X7: Originally Approved on: Arial, Buried, Hybrid | Y7: Allocation Percentage | Z7: Current Status (Live/Not Live) | AA7: Live on (Arial,Buried, Hybrid) | AB7: % of Completion of Work Done | AC7: Compeltion % not % | AD7: Start Date.. | AE7: Start Date OffSet | AF7: Duration | AG7: Days Remaining | AH7: Status | AI7: Timeline | AJ7: Timeline - Monthwise | AK7: Remarks by ODN | AL7: Remarks Grouped | AM7: Std Remarks | AN7: Additional Remarks (5-6M) | AO7: Additional Remarks (5-6M)2 | AP7: Swapped With - | AQ7: Swapped/Removal Budget | AR7: HP - Revised | AS7: 71 vs 26 | AT7: 72 vs 26
A8: I250212 | B8: 45549 | C8: Swat | D8: Mingora | E8: Between Fizaghat & Sangota | F8: 62 | G8: 24.8 | L8: NOC and Civil work pending | M8: =Table8[[#This Row],[Std Remarks]] -> NOT LIVE - RETAIN BUDGET | N8: =Table8[[#This Row],[% of Completion of Work Done]] -> 0 | O8: =Table8[[#This Row],[Customers According to % (Market Share)]] -> 24.8 | P8: 5376147.3 | Q8: =(Table8[[#This Row],[Allocated Budget]]*$Q$2)+(Table8[[#This Row],[Allocated Budget]]*(1-Table8[[#This Row],[HP% based on Live % ( Work Progress)]])*(1-$Q$2)) -> 5376147.3 | R8: 0 | S8: -1 | U8: 0.4 | V8: 1617 | W8: 3172.945 | X8: Hybrid | Y8: =Table8[[#This Row],[% of Completion of Work Done]] -> 0 | Z8: NOT LIVE | AB8: 0 | AC8: =VALUE(SUBSTITUTE(AB8,"%","")) -> 0 | AD8: 46082 | AE8: =IFERROR(Table8[[#This Row],[Timeline - Monthwise]]-MIN(Table8[Start Date..]),"None") -> 92 | AF8: =IFERROR(Table8[[#This Row],[Timeline - Monthwise]]-Table8[[#This Row],[Start Date..]]+1,"Duration Doesn't Exsists") -> 93 | AG8: =IFERROR(Table8[[#This Row],[Timeline - Monthwise]]-TODAY(),"No ETA") -> 45 | AH8: =IF(AB8=100%,"Completed",IF(AB8=0%,"Yet to Start","In Progress")) -> Yet to Start | AI8: 46174 | AJ8: Jun-2026 | AK8: Need to retain | AL8: Not Live - Work to be initiated | AM8: NOT LIVE - RETAIN BUDGET | AN8: 2 | AS8: =VLOOKUP(Table8[[#This Row],[CEM Number]],'71 CEMs'!$E$5:$E$76,1,0) -> I250212 | AT8: 46174
A9: I260296 | B9: No Initiation Date | C9: Sukkur | D9: Sukkur | E9: 100 Feet Rd P1 | F9: 1472 | G9: 588.8 | M9: =Table8[[#This Row],[Std Remarks]] -> NOT LIVE - RETAIN BUDGET | N9: =Table8[[#This Row],[% of Completion of Work Done]] -> 0.7 | P9: 22129453 | Q9: =(Table8[[#This Row],[Allocated Budget]]*$Q$2)+(Table8[[#This Row],[Allocated Budget]]*(1-Table8[[#This Row],[HP% based on Live % ( Work Progress)]])*(1-$Q$2)) -> 8962428.5 | V9: 5111.75 | W9: 19417.636 | X9: Hybrid | Y9: =Table8[[#This Row],[% of Completion of Work Done]] -> 0.7 | Z9: NOT LIVE | AB9: 0.7 | AC9: =VALUE(SUBSTITUTE(AB9,"%","")) -> 0.7 | AD9: 46082 | AE9: =IFERROR(Table8[[#This Row],[Timeline - Monthwise]]-MIN(Table8[Start Date..]),"None") -> 31 | AF9: =IFERROR(Table8[[#This Row],[Timeline - Monthwise]]-Table8[[#This Row],[Start Date..]]+1,"Duration Doesn't Exsists") -> 32 | AG9: =IFERROR(Table8[[#This Row],[Timeline - Monthwise]]-TODAY(),"No ETA") -> -16 | AH9: =IF(AB9=100%,"Completed",IF(AB9=0%,"Yet to Start","In Progress")) -> In Progress | AI9: 1 Month | AJ9: Apr-2026 | AK9: Crossing Pending and Other Civil Related work pending | AL9: Not Live - Work in Progress (WIP) | AM9: NOT LIVE - RETAIN BUDGET | AS9: =VLOOKUP(Table8[[#This Row],[CEM Number]],'71 CEMs'!$E$5:$E$76,1,0) -> #N/A | AT9: 46113
A10: I260296 | B10: No Initiation Date | C10: Sukkur | D10: Sukkur | E10: 100 Feet Rd P2 | F10: 2416 | G10: 966.4 | M10: =Table8[[#This Row],[Std Remarks]] -> NOT LIVE - RETAIN BUDGET | N10: =Table8[[#This Row],[% of Completion of Work Done]] -> 0.7 | P10: 26522964 | Q10: =(Table8[[#This Row],[Allocated Budget]]*$Q$2)+(Table8[[#This Row],[Allocated Budget]]*(1-Table8[[#This Row],[HP% based on Live % ( Work Progress)]])*(1-$Q$2)) -> 10741800 | V10: 4135.4 | W10: 30832.346 | X10: Hybrid | Y10: =Table8[[#This Row],[% of Completion of Work Done]] -> 0.7 | Z10: NOT LIVE | AB10: 0.7 | AC10: =VALUE(SUBSTITUTE(AB10,"%","")) -> 0.7 | AD10: 46082 | AE10: =IFERROR(Table8[[#This Row],[Timeline - Monthwise]]-MIN(Table8[Start Date..]),"None") -> 31 | AF10: =IFERROR(Table8[[#This Row],[Timeline - Monthwise]]-Table8[[#This Row],[Start Date..]]+1,"Duration Doesn't Exsists") -> 32 | AG10: =IFERROR(Table8[[#This Row],[Timeline - Monthwise]]-TODAY(),"No ETA") -> -16 | AH10: =IF(AB10=100%,"Completed",IF(AB10=0%,"Yet to Start","In Progress")) -> In Progress | AI10: 1 Month | AJ10: Apr-2026 | AK10: Crossing Pending and Other Civil Related work pending | AL10: Not Live - Work in Progress (WIP) | AM10: NOT LIVE - RETAIN BUDGET | AS10: =VLOOKUP(Table8[[#This Row],[CEM Number]],'71 CEMs'!$E$5:$E$76,1,0) -> #N/A | AT10: 46113
A11: I240683 | B11: 45427 | C11: Okara | D11: Okara | E11: 1-4L | F11: 708 | G11: 283.2 | H11: 231 | I11: 54 | K11: 177 | M11: =Table8[[#This Row],[Std Remarks]] -> LIVE - 100% Completed | N11: =Table8[[#This Row],[% of Completion of Work Done]] -> 1 | O11: =Table8[[#This Row],[Customers According to % (Market Share)]] -> 283.2 | P11: 14710666 | Q11: =Table8[[#This Row],[Allocated Budget]]*Table8[[#This Row],[Allocation Percentage]] -> 2206599.9 | R11: 12504066 | S11: -1 | U11: 0.4 | V11: 2849.7 | W11: 18016.25 | X11: Hybrid | Y11: =$Q$2 -> 0.15 | Z11: LIVE | AA11: Hybrid | AB11: 1 | AC11: =VALUE(SUBSTITUTE(AB11,"%","")) -> 1 | AD11: 46082 | AE11: =IFERROR(Table8[[#This Row],[Timeline - Monthwise]]-MIN(Table8[Start Date..]),"None") -> None | AF11: =IFERROR(Table8[[#This Row],[Timeline - Monthwise]]-Table8[[#This Row],[Start Date..]]+1,"Duration Doesn't Exsists") -> Duration Doesn't Exsists | AG11: =IFERROR(Table8[[#This Row],[Timeline - Monthwise]]-TODAY(),"No ETA") -> No ETA | AH11: =IF(AB11=100%,"Completed",IF(AB11=0%,"Yet to Start","In Progress")) -> Completed | AJ11: Timeline not applicable | AL11: Live - As per Plan | AM11: LIVE - 100% Completed | AS11: =VLOOKUP(Table8[[#This Row],[CEM Number]],'71 CEMs'!$E$5:$E$76,1,0) -> I240683 | AT11: Timeline not applicable
A12: I240518 | B12: 45349 | C12: Islamabad | D12: Naval Anchorage and other Areas (ISB) | E12: 18_P1 | F12: 888 | G12: 444 | H12: 14 | J12: 2 | K12: 12 | M12: =Table8[[#This Row],[Std Remarks]] -> LIVE - 100% Completed | N12: =Table8[[#This Row],[% of Completion of Work Done]] -> 1 | O12: =Table8[[#This Row],[Customers According to % (Market Share)]] -> 444 | P12: 5022290.1 | Q12: =Table8[[#This Row],[Allocated Budget]]*Table8[[#This Row],[Allocation Percentage]] -> 753343.52 | R12: 4268946.6 | S12: 0 | U12: 0.5 | V12: 1743.75 | W12: 2788.9897 | X12: Buried | Y12: =$Q$2 -> 0.15 | Z12: LIVE | AA12: Buried | AB12: 1 | AC12: =VALUE(SUBSTITUTE(AB12,"%","")) -> 1 | AD12: 46082 | AE12: =IFERROR(Table8[[#This Row],[Timeline - Monthwise]]-MIN(Table8[Start Date..]),"None") -> None | AF12: =IFERROR(Table8[[#This Row],[Timeline - Monthwise]]-Table8[[#This Row],[Start Date..]]+1,"Duration Doesn't Exsists") -> Duration Doesn't Exsists | AG12: =IFERROR(Table8[[#This Row],[Timeline - Monthwise]]-TODAY(),"No ETA") -> No ETA | AH12: =IF(AB12=100%,"Completed",IF(AB12=0%,"Yet to Start","In Progress")) -> Completed | AJ12: Timeline not applicable | AL12: Live - As per Plan | AM12: LIVE - 100% Completed | AS12: =VLOOKUP(Table8[[#This Row],[CEM Number]],'71 CEMs'!$E$5:$E$76,1,0) -> I240518 | AT12: Timeline not applicable
A13: I240518 | B13: 45349 | C13: Islamabad | D13: Naval Anchorage and other Areas (ISB) | E13: 18_P2 | F13: 278 | G13: 139 | H13: 0 | M13: =Table8[[#This Row],[Std Remarks]] -> REMOVE BUDGET (T) | N13: =Table8[[#This Row],[% of Completion of Work Done]] -> 0 | O13: =Table8[[#This Row],[Customers According to % (Market Share)]] -> 139 | P13: 4525188.2 | Q13: 0 | R13: 4525188.2 | S13: -1 | U13: 0.5 | V13: 1706.25 | W13: 6137.5094 | X13: Buried | Z13: NOT LIVE | AB13: 0 | AC13: =VALUE(SUBSTITUTE(AB13,"%","")) -> 0 | AD13: 46082 | AE13: =IFERROR(Table8[[#This Row],[Timeline - Monthwise]]-MIN(Table8[Start Date..]),"None") -> None | AF13: =IFERROR(Table8[[#This Row],[Timeline - Monthwise]]-Table8[[#This Row],[Start Date..]]+1,"Duration Doesn't Exsists") -> Duration Doesn't Exsists | AG13: =IFERROR(Table8[[#This Row],[Timeline - Monthwise]]-TODAY(),"No ETA") -> No ETA | AH13: =IF(AB13=100%,"Completed",IF(AB13=0%,"Yet to Start","In Progress")) -> Yet to Start | AJ13: Timeline not applicable | AK13: remove (after June) | AL13: Temporary Budget Removal | AM13: REMOVE BUDGET (T) | AQ13: =Table8[[#This Row],[Allocated Budget]]-Table8[[#This Row],[Allocated Budget]] -> 0 | AS13: =VLOOKUP(Table8[[#This Row],[CEM Number]],'71 CEMs'!$E$5:$E$76,1,0) -> I240518 | AT13: Timeline not applicable
A14: I240701 | B14: 45428 | C14: Feeders/Transportations | D14: Swat | E14: 24F Cable | F14: 0 | G14: 0 | M14: =Table8[[#This Row],[Std Remarks]] -> FEEDER ETC WORK - RETAIN BUDGET | N14: =Table8[[#This Row],[% of Completion of Work Done]] -> 0 | O14: =Table8[[#This Row],[Customers According to % (Market Share)]] -> 0 | P14: 660000 | Q14: =Table8[[#This Row],[Allocated Budget]]*Table8[[#This Row],[Allocation Percentage]] -> 330000 | R14: 330000 | S14: -1 | V14: 0 | W14: 0 | Y14: =$Q$1 -> 0.5 | AB14: 0 | AC14: =VALUE(SUBSTITUTE(AB14,"%","")) -> 0 | AD14: 46082 | AE14: =IFERROR(Table8[[#This Row],[Timeline - Monthwise]]-MIN(Table8[Start Date..]),"None") -> None | AF14: =IFERROR(Table8[[#This Row],[Timeline - Monthwise]]-Table8[[#This Row],[Start Date..]]+1,"Duration Doesn't Exsists") -> Duration Doesn't Exsists | AG14: =IFERROR(Table8[[#This Row],[Timeline - Monthwise]]-TODAY(),"No ETA") -> No ETA | AH14: =IF(AB14=100%,"Completed",IF(AB14=0%,"Yet to Start","In Progress")) -> Yet to Start | AJ14: Timeline not applicable | AL14: Feeders/Trans | AM14: FEEDER ETC WORK - RETAIN BUDGET | AS14: =VLOOKUP(Table8[[#This Row],[CEM Number]],'71 CEMs'!$E$5:$E$76,1,0) -> I240701 | AT14: Timeline not applicable
A15: I250734 | B15: No Initiation Date | C15: Bahawalpur | D15: Bahwalpur (P2)-B | E15: 3 Marla Scheme | F15: 1730 | G15: 692 | H15: Not Live Yet | M15: =Table8[[#This Row],[Std Remarks]] -> NOT LIVE - RETAIN BUDGET | N15: =Table8[[#This Row],[% of Completion of Work Done]] -> 0.85 | O15: =Table8[[#This Row],[Customers According to % (Market Share)]] -> 692 | P15: 8809572.5 | Q15: =(Table8[[#This Row],[Allocated Budget]]*$Q$2)+(Table8[[#This Row],[Allocated Budget]]*(1-Table8[[#This Row],[HP% based on Live % ( Work Progress)]])*(1-$Q$2)) -> 2444656.4 | V15: 1286.5177 | W15: 9419.8009 | X15: Hybrid | Y15: =Table8[[#This Row],[% of Completion of Work Done]] -> 0.85 | Z15: Not Live | AB15: 0.85 | AC15: =VALUE(SUBSTITUTE(AB15,"%","")) -> 0.85 | AD15: 46082 | AE15: =IFERROR(Table8[[#This Row],[Timeline - Monthwise]]-MIN(Table8[Start Date..]),"None") -> 31 | AF15: =IFERROR(Table8[[#This Row],[Timeline - Monthwise]]-Table8[[#This Row],[Start Date..]]+1,"Duration Doesn't Exsists") -> 32 | AG15: =IFERROR(Table8[[#This Row],[Timeline - Monthwise]]-TODAY(),"No ETA") -> -16 | AH15: =IF(AB15=100%,"Completed",IF(AB15=0%,"Yet to Start","In Progress")) -> In Progress | AI15: 1 Month | AJ15: Apr-2026 | AK15: Cable pulling pending | AL15: Not Live - Work in Progress (WIP) | AM15: NOT LIVE - RETAIN BUDGET | AS15: =VLOOKUP(Table8[[#This Row],[CEM Number]],'71 CEMs'!$E$5:$E$76,1,0) -> #N/A | AT15: 46113
A16: I260599 | B16: No Initiation Date | C16: Dera Ghazi Khan | D16: DG Khan | E16: Adam Housing-P1 | F16: 554 | G16: 249.3 | M16: =Table8[[#This Row],[Std Remarks]] -> NOT LIVE - RETAIN BUDGET | N16: =Table8[[#This Row],[% of Completion of Work Done]] -> 0 | O16: =Table8[[#This Row],[Customers According to % (Market Share)]] -> 249.3 | P16: 16702836 | Q16: =(Table8[[#This Row],[Allocated Budget]]*$Q$2)+(Table8[[#This Row],[Allocated Budget]]*(1-Table8[[#This Row],[HP% based on Live % ( Work Progress)]])*(1-$Q$2)) -> 16702836 | U16: 0.45 | V16: 8363.7 | W16: 7443 | X16: Hybrid | Y16: =Table8[[#This Row],[% of Completion of Work Done]] -> 0 | Z16: NOT LIVE | AB16: 0 | AC16: =VALUE(SUBSTITUTE(AB16,"%","")) -> 0 | AD16: 46082 | AE16: =IFERROR(Table8[[#This Row],[Timeline - Monthwise]]-MIN(Table8[Start Date..]),"None") -> 214 | AF16: =IFERROR(Table8[[#This Row],[Timeline - Monthwise]]-Table8[[#This Row],[Start Date..]]+1,"Duration Doesn't Exsists") -> 215 | AG16: =IFERROR(Table8[[#This Row],[Timeline - Monthwise]]-TODAY(),"No ETA") -> 167 | AH16: =IF(AB16=100%,"Completed",IF(AB16=0%,"Yet to Start","In Progress")) -> Yet to Start | AI16: 6 Months | AJ16: Oct-2026 | AK16: These Projects have not been started yet, proceedings shall be done post eid | AL16: Not Live - Work to be initiated | AM16: NOT LIVE - RETAIN BUDGET | AS16: =VLOOKUP(Table8[[#This Row],[CEM Number]],'71 CEMs'!$E$5:$E$76,1,0) -> #N/A | AT16: 46296
A17: I260599 | B17: No Initiation Date | C17: Dera Ghazi Khan | D17: DG Khan | E17: Adam Housing-P2 | F17: 428 | G17: 192.6 | M17: =Table8[[#This Row],[Std Remarks]] -> NOT LIVE - RETAIN BUDGET | N17: =Table8[[#This Row],[% of Completion of Work Done]] -> 0 | O17: =Table8[[#This Row],[Customers According to % (Market Share)]] -> 192.6 | P17: 14769070 | Q17: =(Table8[[#This Row],[Allocated Budget]]*$Q$2)+(Table8[[#This Row],[Allocated Budget]]*(1-Table8[[#This Row],[HP% based on Live % ( Work Progress)]])*(1-$Q$2)) -> 14769070 | U17: 0.45 | V17: 7360.65 | W17: 6328.5 | X17: Hybrid | Y17: =Table8[[#This Row],[% of Completion of Work Done]] -> 0 | Z17: NOT LIVE | AB17: 0 | AC17: =VALUE(SUBSTITUTE(AB17,"%","")) -> 0 | AD17: 46082 | AE17: =IFERROR(Table8[[#This Row],[Timeline - Monthwise]]-MIN(Table8[Start Date..]),"None") -> 214 | AF17: =IFERROR(Table8[[#This Row],[Timeline - Monthwise]]-Table8[[#This Row],[Start Date..]]+1,"Duration Doesn't Exsists") -> 215 | AG17: =IFERROR(Table8[[#This Row],[Timeline - Monthwise]]-TODAY(),"No ETA") -> 167 | AH17: =IF(AB17=100%,"Completed",IF(AB17=0%,"Yet to Start","In Progress")) -> Yet to Start | AI17: 6 Months | AJ17: Oct-2026 | AK17: These Projects have not been started yet, proceedings shall be done post eid | AL17: Not Live - Work to be initiated | AM17: NOT LIVE - RETAIN BUDGET | AS17: =VLOOKUP(Table8[[#This Row],[CEM Number]],'71 CEMs'!$E$5:$E$76,1,0) -> #N/A | AT17: 46296
A18: I240540 | B18: 45350 | C18: Mardan | D18: Mardan Ph2 | E18: Abdullah Colony & Nawa Killy | F18: 394 | G18: 157.6 | H18: 394 | I18: 13 | J18: 12 | K18: 1 | L18: 0 | N18: =Table8[[#This Row],[% of Completion of Work Done]] -> 1 | O18: =Table8[[#This Row],[Customers According to % (Market Share)]] -> 157.6 | P18: 7472398.9 | Q18: =Table8[[#This Row],[Allocated Budget]]*Table8[[#This Row],[Allocation Percentage]] -> 1120859.8 | R18: 6351539.1 | S18: -1 | U18: 0.4 | V18: 0 | W18: 19592.513 | X18: Hybrid | Y18: =$Q$2 -> 0.15 | Z18: LIVE | AA18: Hybrid | AB18: 1 | AC18: =VALUE(SUBSTITUTE(AB18,"%","")) -> 1 | AD18: 46082 | AE18: =IFERROR(Table8[[#This Row],[Timeline - Monthwise]]-MIN(Table8[Start Date..]),"None") -> None | AF18: =IFERROR(Table8[[#This Row],[Timeline - Monthwise]]-Table8[[#This Row],[Start Date..]]+1,"Duration Doesn't Exsists") -> Duration Doesn't Exsists | AG18: =IFERROR(Table8[[#This Row],[Timeline - Monthwise]]-TODAY(),"No ETA") -> No ETA | AH18: =IF(AB18=100%,"Completed",IF(AB18=0%,"Yet to Start","In Progress")) -> Completed | AJ18: Timeline not applicable | AL18: Live - As per Plan | AM18: LIVE - 100% Completed | AS18: =VLOOKUP(Table8[[#This Row],[CEM Number]],'71 CEMs'!$E$5:$E$76,1,0) -> I240540 | AT18: Timeline not applicable
A19: I240702 | B19: 45427 | C19: Hyderabad | D19: Hyderabad | E19: Abdullah Sports Tower Ext | F19: 96 | G19: 38.4 | H19: 58 | I19: 0 | M19: =Table8[[#This Row],[Std Remarks]] -> NOT LIVE - RETAIN BUDGET | N19: =Table8[[#This Row],[% of Completion of Work Done]] -> 1 | O19: =Table8[[#This Row],[Customers According to % (Market Share)]] -> 38.4 | P19: 3652917.5 | Q19: =(Table8[[#This Row],[Allocated Budget]]*$Q$2)+(Table8[[#This Row],[Allocated Budget]]*(1-Table8[[#This Row],[HP% based on Live % ( Work Progress)]])*(1-$Q$2)) -> 547937.62 | R19: 3104979.9 | S19: -1 | U19: 0.4 | V19: 1375.8562 | W19: 840.29761 | X19: Buried | Y19: =Table8[[#This Row],[% of Completion of Work Done]] -> 1 | Z19: NOT LIVE | AB19: 1 | AC19: =VALUE(SUBSTITUTE(AB19,"%","")) -> 1 | AD19: 46082 | AE19: =IFERROR(Table8[[#This Row],[Timeline - Monthwise]]-MIN(Table8[Start Date..]),"None") -> 92 | AF19: =IFERROR(Table8[[#This Row],[Timeline - Monthwise]]-Table8[[#This Row],[Start Date..]]+1,"Duration Doesn't Exsists") -> 93 | AG19: =IFERROR(Table8[[#This Row],[Timeline - Monthwise]]-TODAY(),"No ETA") -> 45 | AH19: =IF(AB19=100%,"Completed",IF(AB19=0%,"Yet to Start","In Progress")) -> Completed | AI19: 46174 | AJ19: Jun-2026 | AK19: Civil work completed, but not live due to pending customer possession from the builder. | AL19: Not Live - Work in Progress (WIP) | AM19: NOT LIVE - RETAIN BUDGET | AN19: 1 | AS19: =VLOOKUP(Table8[[#This Row],[CEM Number]],'71 CEMs'!$E$5:$E$76,1,0) -> I240702 | AT19: 46174
A20: I260599 | B20: No Initiation Date | C20: Dera Ghazi Khan | D20: DG Khan | E20: Al Hussain Garden | F20: 228 | G20: 102.6 | M20: =Table8[[#This Row],[Std Remarks]] -> NOT LIVE - RETAIN BUDGET | N20: =Table8[[#This Row],[% of Completion of Work Done]] -> 0 | O20: =Table8[[#This Row],[Customers According to % (Market Share)]] -> 102.6 | P20: 6341933 | Q20: =(Table8[[#This Row],[Allocated Budget]]*$Q$2)+(Table8[[#This Row],[Allocated Budget]]*(1-Table8[[#This Row],[HP% based on Live % ( Work Progress)]])*(1-$Q$2)) -> 6341933 | U20: 0.45 | V20: 3085.35 | W20: 2785.5 | X20: Hybrid | Y20: =Table8[[#This Row],[% of Completion of Work Done]] -> 0 | Z20: NOT LIVE | AB20: 0 | AC20: =VALUE(SUBSTITUTE(AB20,"%","")) -> 0 | AD20: 46082 | AE20: =IFERROR(Table8[[#This Row],[Timeline - Monthwise]]-MIN(Table8[Start Date..]),"None") -> 214 | AF20: =IFERROR(Table8[[#This Row],[Timeline - Monthwise]]-Table8[[#This Row],[Start Date..]]+1,"Duration Doesn't Exsists") -> 215 | AG20: =IFERROR(Table8[[#This Row],[Timeline - Monthwise]]-TODAY(),"No ETA") -> 167 | AH20: =IF(AB20=100%,"Completed",IF(AB20=0%,"Yet to Start","In Progress")) -> Yet to Start | AI20: 6 Months | AJ20: Oct-2026 | AK20: These Projects have not been started yet, proceedings shall be done post eid | AL20: Not Live - Work to be initiated | AM20: NOT LIVE - RETAIN BUDGET | AS20: =VLOOKUP(Table8[[#This Row],[CEM Number]],'71 CEMs'!$E$5:$E$76,1,0) -> #N/A | AT20: 46296
A21: I240703 | B21: 45427 | C21: Lahore | D21: Lahore Ph5 | E21: Abid Market | F21: 656 | G21: 262.4 | M21: =Table8[[#This Row],[Std Remarks]] -> NOT LIVE - RETAIN BUDGET | N21: =Table8[[#This Row],[% of Completion of Work Done]] -> 0.8 | O21: =Table8[[#This Row],[Customers According to % (Market Share)]] -> 262.4 | P21: 7827127.3 | Q21: =(Table8[[#This Row],[Allocated Budget]]*$Q$2)+(Table8[[#This Row],[Allocated Budget]]*(1-Table8[[#This Row],[HP% based on Live % ( Work Progress)]])*(1-$Q$2)) -> 2504680.7 | R21: 5322446.6 | S21: -1 | U21: 0.4 | V21: 874 | W21: 2022.5 | X21: Hybrid | Y21: =Table8[[#This Row],[% of Completion of Work Done]] -> 0.8 | Z21: NOT LIVE | AB21: 0.8 | AC21: =VALUE(SUBSTITUTE(AB21,"%","")) -> 0.8 | AD21: 46082 | AE21: =IFERROR(Table8[[#This Row],[Timeline - Monthwise]]-MIN(Table8[Start Date..]),"None") -> 0 | AF21: =IFERROR(Table8[[#This Row],[Timeline - Monthwise]]-Table8[[#This Row],[Start Date..]]+1,"Duration Doesn't Exsists") -> 1 | AG21: =IFERROR(Table8[[#This Row],[Timeline - Monthwise]]-TODAY(),"No ETA") -> -47 | AH21: =IF(AB21=100%,"Completed",IF(AB21=0%,"Yet to Start","In Progress")) -> In Progress | AI21: 46054 | AJ21: Mar-2026 | AK21: Cable pulling pending | AL21: Not Live - Work in Progress (WIP) | AM21: NOT LIVE - RETAIN BUDGET | AN21: 1 | AS21: =VLOOKUP(Table8[[#This Row],[CEM Number]],'71 CEMs'!$E$5:$E$76,1,0) -> I240703 | AT21: 46082
A22: I240705 | B22: 45427 | C22: Karachi | D22: Karachi Ph5 | E22: AbrazulMinal_KingsBridgeView | F22: 1400 | G22: 560 | M22: =Table8[[#This Row],[Std Remarks]] -> NOT LIVE - RETAIN BUDGET | N22: =Table8[[#This Row],[% of Completion of Work Done]] -> 0 | O22: =Table8[[#This Row],[Customers According to % (Market Share)]] -> 560 | P22: 4430148.1 | Q22: =(Table8[[#This Row],[Allocated Budget]]*$Q$2)+(Table8[[#This Row],[Allocated Budget]]*(1-Table8[[#This Row],[HP% based on Live % ( Work Progress)]])*(1-$Q$2)) -> 4430148.1 | R22: 0 | S22: -0.833 | U22: 0.4 | V22: 415.14421 | W22: 1275.481 | X22: Hybrid | Y22: =Table8[[#This Row],[% of Completion of Work Done]] -> 0 | Z22: NOT LIVE | AB22: 0 | AC22: =VALUE(SUBSTITUTE(AB22,"%","")) -> 0 | AD22: 46082 | AE22: =IFERROR(Table8[[#This Row],[Timeline - Monthwise]]-MIN(Table8[Start Date..]),"None") -> 31 | AF22: =IFERROR(Table8[[#This Row],[Timeline - Monthwise]]-Table8[[#This Row],[Start Date..]]+1,"Duration Doesn't Exsists") -> 32 | AG22: =IFERROR(Table8[[#This Row],[Timeline - Monthwise]]-TODAY(),"No ETA") -> -16 | AH22: =IF(AB22=100%,"Completed",IF(AB22=0%,"Yet to Start","In Progress")) -> Yet to Start | AI22: 46204 | AJ22: Apr-2026 | AK22: Permission Issue | AL22: Not Live - Permission Issues | AM22: NOT LIVE - RETAIN BUDGET | AN22: 2 | AS22: =VLOOKUP(Table8[[#This Row],[CEM Number]],'71 CEMs'!$E$5:$E$76,1,0) -> I240705 | AT22: 46113
A23: I240704 | B23: 45427 | C23: Multan | D23: Multan Ph3 | E23: Adam Housing | F23: 1130 | G23: 452 | H23: 0 | I23: 0 | J23: 0 | K23: 0 | L23: Budget Shifted | M23: =Table8[[#This Row],[Std Remarks]] -> LIVE - 100% Completed | N23: =Table8[[#This Row],[% of Completion of Work Done]] -> 1 | O23: =Table8[[#This Row],[Customers According to % (Market Share)]] -> 452 | P23: 36999249 | Q23: =Table8[[#This Row],[Allocated Budget]]*Table8[[#This Row],[Allocation Percentage]] -> 5549887.3 | R23: 31449362 | S23: #DIV/0! | U23: 0.4 | V23: 18159.3 | W23: 13746 | X23: Buried | Y23: =$Q$2 -> 0.15 | Z23: LIVE | AA23: Buried | AB23: 1 | AC23: =VALUE(SUBSTITUTE(AB23,"%","")) -> 1 | AD23: 46082 | AE23: =IFERROR(Table8[[#This Row],[Timeline - Monthwise]]-MIN(Table8[Start Date..]),"None") -> None | AF23: =IFERROR(Table8[[#This Row],[Timeline - Monthwise]]-Table8[[#This Row],[Start Date..]]+1,"Duration Doesn't Exsists") -> Duration Doesn't Exsists | AG23: =IFERROR(Table8[[#This Row],[Timeline - Monthwise]]-TODAY(),"No ETA") -> No ETA | AH23: =IF(AB23=100%,"Completed",IF(AB23=0%,"Yet to Start","In Progress")) -> Completed | AJ23: Timeline not applicable | AK23: Swapped with Manic Block Buch Villas | AL23: Swap Cases | AM23: LIVE - 100% Completed | AS23: =VLOOKUP(Table8[[#This Row],[CEM Number]],'71 CEMs'!$E$5:$E$76,1,0) -> I240704 | AT23: Timeline not applicable
A24: I260599 | B24: No Initiation Date | C24: Dera Ghazi Khan | D24: DG Khan | E24: Al Inam Gardens | F24: 316 | G24: 142.2 | M24: =Table8[[#This Row],[Std Remarks]] -> NOT LIVE - RETAIN BUDGET | N24: =Table8[[#This Row],[% of Completion of Work Done]] -> 0 | O24: =Table8[[#This Row],[Customers According to % (Market Share)]] -> 142.2 | P24: 10497665 | Q24: =(Table8[[#This Row],[Allocated Budget]]*$Q$2)+(Table8[[#This Row],[Allocated Budget]]*(1-Table8[[#This Row],[HP% based on Live % ( Work Progress)]])*(1-$Q$2)) -> 10497665 | U24: 0.45 | V24: 5045.6 | W24: 4503.7 | X24: Hybrid | Y24: =Table8[[#This Row],[% of Completion of Work Done]] -> 0 | Z24: NOT LIVE | AB24: 0 | AC24: =VALUE(SUBSTITUTE(AB24,"%","")) -> 0 | AD24: 46082 | AE24: =IFERROR(Table8[[#This Row],[Timeline - Monthwise]]-MIN(Table8[Start Date..]),"None") -> 214 | AF24: =IFERROR(Table8[[#This Row],[Timeline - Monthwise]]-Table8[[#This Row],[Start Date..]]+1,"Duration Doesn't Exsists") -> 215 | AG24: =IFERROR(Table8[[#This Row],[Timeline - Monthwise]]-TODAY(),"No ETA") -> 167 | AH24: =IF(AB24=100%,"Completed",IF(AB24=0%,"Yet to Start","In Progress")) -> Yet to Start | AI24: 6 Months | AJ24: Oct-2026 | AK24: These Projects have not been started yet, proceedings shall be done post eid | AL24: Not Live - Work to be initiated | AM24: NOT LIVE - RETAIN BUDGET | AS24: =VLOOKUP(Table8[[#This Row],[CEM Number]],'71 CEMs'!$E$5:$E$76,1,0) -> #N/A | AT24: 46296
A25: I260599 | B25: No Initiation Date | C25: Dera Ghazi Khan | D25: DG Khan | E25: Al Rasool Town | F25: 310 | G25: 139.5 | M25: =Table8[[#This Row],[Std Remarks]] -> NOT LIVE - RETAIN BUDGET | N25: =Table8[[#This Row],[% of Completion of Work Done]] -> 0 | O25: =Table8[[#This Row],[Customers According to % (Market Share)]] -> 139.5 | P25: 9129729 | Q25: =(Table8[[#This Row],[Allocated Budget]]*$Q$2)+(Table8[[#This Row],[Allocated Budget]]*(1-Table8[[#This Row],[HP% based on Live % ( Work Progress)]])*(1-$Q$2)) -> 9129729 | U25: 0.45 | V25: 4880.9 | W25: 4476 | X25: Hybrid | Y25: =Table8[[#This Row],[% of Completion of Work Done]] -> 0 | Z25: NOT LIVE | AB25: 0 | AC25: =VALUE(SUBSTITUTE(AB25,"%","")) -> 0 | AD25: 46082 | AE25: =IFERROR(Table8[[#This Row],[Timeline - Monthwise]]-MIN(Table8[Start Date..]),"None") -> 214 | AF25: =IFERROR(Table8[[#This Row],[Timeline - Monthwise]]-Table8[[#This Row],[Start Date..]]+1,"Duration Doesn't Exsists") -> 215 | AG25: =IFERROR(Table8[[#This Row],[Timeline - Monthwise]]-TODAY(),"No ETA") -> 167 | AH25: =IF(AB25=100%,"Completed",IF(AB25=0%,"Yet to Start","In Progress")) -> Yet to Start | AI25: 6 Months | AJ25: Oct-2026 | AK25: These Projects have not been started yet, proceedings shall be done post eid | AL25: Not Live - Work to be initiated | AM25: NOT LIVE - RETAIN BUDGET | AS25: =VLOOKUP(Table8[[#This Row],[CEM Number]],'71 CEMs'!$E$5:$E$76,1,0) -> #N/A | AT25: 46296
A26: I260599 | B26: No Initiation Date | C26: Dera Ghazi Khan | D26: DG Khan | E26: Canal View | F26: 582 | G26: 261.9 | M26: =Table8[[#This Row],[Std Remarks]] -> NOT LIVE - RETAIN BUDGET | N26: =Table8[[#This Row],[% of Completion of Work Done]] -> 0 | O26: =Table8[[#This Row],[Customers According to % (Market Share)]] -> 261.9 | P26: 5787365.8 | Q26: =(Table8[[#This Row],[Allocated Budget]]*$Q$2)+(Table8[[#This Row],[Allocated Budget]]*(1-Table8[[#This Row],[HP% based on Live % ( Work Progress)]])*(1-$Q$2)) -> 5787365.8 | U26: 0.45 | V26: 998.4 | W26: 4521.0697 | X26: Hybrid | Y26: =Table8[[#This Row],[% of Completion of Work Done]] -> 0 | Z26: NOT LIVE | AB26: 0 | AC26: =VALUE(SUBSTITUTE(AB26,"%","")) -> 0 | AD26: 46082 | AE26: =IFERROR(Table8[[#This Row],[Timeline - Monthwise]]-MIN(Table8[Start Date..]),"None") -> 214 | AF26: =IFERROR(Table8[[#This Row],[Timeline - Monthwise]]-Table8[[#This Row],[Start Date..]]+1,"Duration Doesn't Exsists") -> 215 | AG26: =IFERROR(Table8[[#This Row],[Timeline - Monthwise]]-TODAY(),"No ETA") -> 167 | AH26: =IF(AB26=100%,"Completed",IF(AB26=0%,"Yet to Start","In Progress")) -> Yet to Start | AI26: 6 Months | AJ26: Oct-2026 | AK26: These Projects have not been started yet, proceedings shall be done post eid | AL26: Not Live - Work to be initiated | AM26: NOT LIVE - RETAIN BUDGET | AS26: =VLOOKUP(Table8[[#This Row],[CEM Number]],'71 CEMs'!$E$5:$E$76,1,0) -> #N/A | AT26: 46296
A27: I240705 | B27: 45427 | C27: Karachi | D27: Karachi Ph5 | E27: AFOHS PK-1 | F27: 984 | G27: 393.6 | M27: =Table8[[#This Row],[Std Remarks]] -> LIVE - 100% Completed | N27: =Table8[[#This Row],[% of Completion of Work Done]] -> 1 | O27: =Table8[[#This Row],[Customers According to % (Market Share)]] -> 393.6 | P27: 52832203 | Q27: =Table8[[#This Row],[Allocated Budget]]*Table8[[#This Row],[Allocation Percentage]] -> 7924830.5 | R27: 44907373 | S27: -1 | U27: 0.4 | V27: 25051.586 | W27: 17445.469 | X27: Buried | Y27: =$Q$2 -> 0.15 | Z27: LIVE | AA27: Buried | AB27: 1 | AC27: =VALUE(SUBSTITUTE(AB27,"%","")) -> 1 | AD27: 46082 | AE27: =IFERROR(Table8[[#This Row],[Timeline - Monthwise]]-MIN(Table8[Start Date..]),"None") -> None | AF27: =IFERROR(Table8[[#This Row],[Timeline - Monthwise]]-Table8[[#This Row],[Start Date..]]+1,"Duration Doesn't Exsists") -> Duration Doesn't Exsists | AG27: =IFERROR(Table8[[#This Row],[Timeline - Monthwise]]-TODAY(),"No ETA") -> No ETA | AH27: =IF(AB27=100%,"Completed",IF(AB27=0%,"Yet to Start","In Progress")) -> Completed | AJ27: Timeline not applicable | AL27: Live - As per Plan | AM27: LIVE - 100% Completed | AS27: =VLOOKUP(Table8[[#This Row],[CEM Number]],'71 CEMs'!$E$5:$E$76,1,0) -> I240705 | AT27: Timeline not applicable
A28: I240705 | B28: 45427 | C28: Karachi | D28: Karachi Ph5 | E28: AFOHS PK-2 | F28: 478 | G28: 191.2 | M28: =Table8[[#This Row],[Std Remarks]] -> LIVE - 100% Completed | N28: =Table8[[#This Row],[% of Completion of Work Done]] -> 1 | O28: =Table8[[#This Row],[Customers According to % (Market Share)]] -> 191.2 | P28: 23923706 | Q28: =Table8[[#This Row],[Allocated Budget]]*Table8[[#This Row],[Allocation Percentage]] -> 3588555.9 | R28: 20335150 | S28: -0.765 | U28: 0.4 | V28: 11643.157 | W28: 9277.2194 | X28: Buried | Y28: =$Q$2 -> 0.15 | Z28: LIVE | AA28: Buried | AB28: 1 | AC28: =VALUE(SUBSTITUTE(AB28,"%","")) -> 1 | AD28: 46082 | AE28: =IFERROR(Table8[[#This Row],[Timeline - Monthwise]]-MIN(Table8[Start Date..]),"None") -> None | AF28: =IFERROR(Table8[[#This Row],[Timeline - Monthwise]]-Table8[[#This Row],[Start Date..]]+1,"Duration Doesn't Exsists") -> Duration Doesn't Exsists | AG28: =IFERROR(Table8[[#This Row],[Timeline - Monthwise]]-TODAY(),"No ETA") -> No ETA | AH28: =IF(AB28=100%,"Completed",IF(AB28=0%,"Yet to Start","In Progress")) -> Completed | AJ28: Timeline not applicable | AL28: Live - As per Plan | AM28: LIVE - 100% Completed | AS28: =VLOOKUP(Table8[[#This Row],[CEM Number]],'71 CEMs'!$E$5:$E$76,1,0) -> I240705 | AT28: Timeline not applicable
A29: I240705 | B29: 45427 | C29: Karachi | D29: Karachi Ph5 | E29: AFOHS PK-3 | F29: 1256 | G29: 502.4 | M29: =Table8[[#This Row],[Std Remarks]] -> NOT LIVE - RETAIN BUDGET | N29: =Table8[[#This Row],[% of Completion of Work Done]] -> 0 | O29: =Table8[[#This Row],[Customers According to % (Market Share)]] -> 502.4 | P29: 64454759 | Q29: =(Table8[[#This Row],[Allocated Budget]]*$Q$2)+(Table8[[#This Row],[Allocated Budget]]*(1-Table8[[#This Row],[HP% based on Live % ( Work Progress)]])*(1-$Q$2)) -> 64454759 | R29: 0 | S29: -1 | U29: 0.4 | V29: 29179.386 | W29: 25756.043 | X29: Buried | Y29: =Table8[[#This Row],[% of Completion of Work Done]] -> 0 | Z29: NOT LIVE | AB29: 0 | AC29: =VALUE(SUBSTITUTE(AB29,"%","")) -> 0 | AD29: 46082 | AE29: =IFERROR(Table8[[#This Row],[Timeline - Monthwise]]-MIN(Table8[Start Date..]),"None") -> 92 | AF29: =IFERROR(Table8[[#This Row],[Timeline - Monthwise]]-Table8[[#This Row],[Start Date..]]+1,"Duration Doesn't Exsists") -> 93 | AG29: =IFERROR(Table8[[#This Row],[Timeline - Monthwise]]-TODAY(),"No ETA") -> 45 | AH29: =IF(AB29=100%,"Completed",IF(AB29=0%,"Yet to Start","In Progress")) -> Yet to Start | AI29: 46174 | AJ29: Jun-2026 | AK29: Need to retain | AL29: Not Live - Work to be initiated | AM29: NOT LIVE - RETAIN BUDGET | AN29: 1 | AS29: =VLOOKUP(Table8[[#This Row],[CEM Number]],'71 CEMs'!$E$5:$E$76,1,0) -> I240705 | AT29: 46174
A30: INT-23-00445 | B30: 44924 | C30: Rawalpindi | D30: Rawalpindi Misc Areas | E30: Afzal Town Expansion(Aerial) | F30: 1428 | G30: 714 | H30: 245 | I30: 49 | J30: 53 | K30: 143 | M30: =Table8[[#This Row],[Std Remarks]] -> LIVE - 100% Completed | N30: =Table8[[#This Row],[% of Completion of Work Done]] -> 1 | O30: =Table8[[#This Row],[Customers According to % (Market Share)]] -> 714 | P30: 9210946.3 | Q30: =Table8[[#This Row],[Allocated Budget]]*Table8[[#This Row],[Allocation Percentage]] -> 1381641.9 | R30: 7829304.4 | S30: #DIV/0! | U30: 0.5 | V30: 0 | W30: 12237.876 | X30: Arial | Y30: =$Q$2 -> 0.15 | Z30: LIVE | AA30: Arial | AB30: 1 | AC30: =VALUE(SUBSTITUTE(AB30,"%","")) -> 1 | AD30: 46082 | AE30: =IFERROR(Table8[[#This Row],[Timeline - Monthwise]]-MIN(Table8[Start Date..]),"None") -> None | AF30: =IFERROR(Table8[[#This Row],[Timeline - Monthwise]]-Table8[[#This Row],[Start Date..]]+1,"Duration Doesn't Exsists") -> Duration Doesn't Exsists | AG30: =IFERROR(Table8[[#This Row],[Timeline - Monthwise]]-TODAY(),"No ETA") -> No ETA | AH30: =IF(AB30=100%,"Completed",IF(AB30=0%,"Yet to Start","In Progress")) -> Completed | AJ30: Timeline not applicable | AL30: Live - As per Plan | AM30: LIVE - 100% Completed | AS30: =VLOOKUP(Table8[[#This Row],[CEM Number]],'71 CEMs'!$E$5:$E$76,1,0) -> INT-23-00445 | AT30: Timeline not applicable
A31: I250212 | B31: 45549 | C31: Swat | D31: Mingora | E31: Airport (Ghanshal village) P01 | F31: 266 | G31: 106.4 | H31: 121 | I31: 107 | J31: 9 | K31: 5 | M31: =Table8[[#This Row],[Std Remarks]] -> LIVE - 100% Completed | N31: =Table8[[#This Row],[% of Completion of Work Done]] -> 1 | O31: =Table8[[#This Row],[Customers According to % (Market Share)]] -> 106.4 | P31: 2211881.5 | Q31: =Table8[[#This Row],[Allocated Budget]]*Table8[[#This Row],[Allocation Percentage]] -> 331782.22 | R31: 1880099.2 | S31: -1 | U31: 0.4 | V31: 0 | W31: 2931.9471 | X31: Arial | Y31: =$Q$2 -> 0.15 | Z31: LIVE | AA31: Arial | AB31: 1 | AC31: =VALUE(SUBSTITUTE(AB31,"%","")) -> 1 | AD31: 46082 | AE31: =IFERROR(Table8[[#This Row],[Timeline - Monthwise]]-MIN(Table8[Start Date..]),"None") -> None | AF31: =IFERROR(Table8[[#This Row],[Timeline - Monthwise]]-Table8[[#This Row],[Start Date..]]+1,"Duration Doesn't Exsists") -> Duration Doesn't Exsists | AG31: =IFERROR(Table8[[#This Row],[Timeline - Monthwise]]-TODAY(),"No ETA") -> No ETA | AH31: =IF(AB31=100%,"Completed",IF(AB31=0%,"Yet to Start","In Progress")) -> Completed | AJ31: Timeline not applicable | AL31: Live - As per Plan | AM31: LIVE - 100% Completed | AS31: =VLOOKUP(Table8[[#This Row],[CEM Number]],'71 CEMs'!$E$5:$E$76,1,0) -> I250212 | AT31: Timeline not applicable
A32: I250212 | B32: 45549 | C32: Swat | D32: Mingora | E32: Airport (Ghanshal village) P01 | F32: 234 | G32: 93.6 | H32: 108 | I32: 95 | J32: 6 | K32: 7 | M32: =Table8[[#This Row],[Std Remarks]] -> LIVE - 100% Completed | N32: =Table8[[#This Row],[% of Completion of Work Done]] -> 1 | O32: =Table8[[#This Row],[Customers According to % (Market Share)]] -> 93.6 | P32: 1910813 | Q32: =Table8[[#This Row],[Allocated Budget]]*Table8[[#This Row],[Allocation Percentage]] -> 286621.96 | R32: 1624191.1 | S32: -0.85 | U32: 0.4 | V32: 0 | W32: 3442.6945 | X32: Arial | Y32: =$Q$2 -> 0.15 | Z32: LIVE | AA32: Arial | AB32: 1 | AC32: =VALUE(SUBSTITUTE(AB32,"%","")) -> 1 | AD32: 46082 | AE32: =IFERROR(Table8[[#This Row],[Timeline - Monthwise]]-MIN(Table8[Start Date..]),"None") -> None | AF32: =IFERROR(Table8[[#This Row],[Timeline - Monthwise]]-Table8[[#This Row],[Start Date..]]+1,"Duration Doesn't Exsists") -> Duration Doesn't Exsists | AG32: =IFERROR(Table8[[#This Row],[Timeline - Monthwise]]-TODAY(),"No ETA") -> No ETA | AH32: =IF(AB32=100%,"Completed",IF(AB32=0%,"Yet to Start","In Progress")) -> Completed | AJ32: Timeline not applicable | AL32: Live - As per Plan | AM32: LIVE - 100% Completed | AS32: =VLOOKUP(Table8[[#This Row],[CEM Number]],'71 CEMs'!$E$5:$E$76,1,0) -> I250212 | AT32: Timeline not applicable
A33: I260599 | B33: No Initiation Date | C33: Dera Ghazi Khan | D33: DG Khan | E33: CPC Colony | F33: 346 | G33: 155.7 | M33: =Table8[[#This Row],[Std Remarks]] -> NOT LIVE - RETAIN BUDGET | N33: =Table8[[#This Row],[% of Completion of Work Done]] -> 0 | O33: =Table8[[#This Row],[Customers According to % (Market Share)]] -> 155.7 | P33: 6395179.5 | Q33: =(Table8[[#This Row],[Allocated Budget]]*$Q$2)+(Table8[[#This Row],[Allocated Budget]]*(1-Table8[[#This Row],[HP% based on Live % ( Work Progress)]])*(1-$Q$2)) -> 6395179.5 | U33: 0.45 | V33: 1705.2 | W33: 5519.602 | X33: Hybrid | Y33: =Table8[[#This Row],[% of Completion of Work Done]] -> 0 | Z33: NOT LIVE | AB33: 0 | AC33: =VALUE(SUBSTITUTE(AB33,"%","")) -> 0 | AD33: 46082 | AE33: =IFERROR(Table8[[#This Row],[Timeline - Monthwise]]-MIN(Table8[Start Date..]),"None") -> 214 | AF33: =IFERROR(Table8[[#This Row],[Timeline - Monthwise]]-Table8[[#This Row],[Start Date..]]+1,"Duration Doesn't Exsists") -> 215 | AG33: =IFERROR(Table8[[#This Row],[Timeline - Monthwise]]-TODAY(),"No ETA") -> 167 | AH33: =IF(AB33=100%,"Completed",IF(AB33=0%,"Yet to Start","In Progress")) -> Yet to Start | AI33: 6 Months | AJ33: Oct-2026 | AK33: These Projects have not been started yet, proceedings shall be done post eid | AL33: Not Live - Work to be initiated | AM33: NOT LIVE - RETAIN BUDGET | AS33: =VLOOKUP(Table8[[#This Row],[CEM Number]],'71 CEMs'!$E$5:$E$76,1,0) -> #N/A | AT33: 46296
A34: I260599 | B34: No Initiation Date | C34: Dera Ghazi Khan | D34: DG Khan | E34: Dream City | F34: 532 | G34: 239.4 | M34: =Table8[[#This Row],[Std Remarks]] -> NOT LIVE - RETAIN BUDGET | N34: =Table8[[#This Row],[% of Completion of Work Done]] -> 0 | O34: =Table8[[#This Row],[Customers According to % (Market Share)]] -> 239.4 | P34: 15928200 | Q34: =(Table8[[#This Row],[Allocated Budget]]*$Q$2)+(Table8[[#This Row],[Allocated Budget]]*(1-Table8[[#This Row],[HP% based on Live % ( Work Progress)]])*(1-$Q$2)) -> 15928200 | U34: 0.45 | V34: 7953.9 | W34: 7119 | X34: Hybrid | Y34: =Table8[[#This Row],[% of Completion of Work Done]] -> 0 | Z34: NOT LIVE | AB34: 0 | AC34: =VALUE(SUBSTITUTE(AB34,"%","")) -> 0 | AD34: 46082 | AE34: =IFERROR(Table8[[#This Row],[Timeline - Monthwise]]-MIN(Table8[Start Date..]),"None") -> 214 | AF34: =IFERROR(Table8[[#This Row],[Timeline - Monthwise]]-Table8[[#This Row],[Start Date..]]+1,"Duration Doesn't Exsists") -> 215 | AG34: =IFERROR(Table8[[#This Row],[Timeline - Monthwise]]-TODAY(),"No ETA") -> 167 | AH34: =IF(AB34=100%,"Completed",IF(AB34=0%,"Yet to Start","In Progress")) -> Yet to Start | AI34: 6 Months | AJ34: Oct-2026 | AK34: These Projects have not been started yet, proceedings shall be done post eid | AL34: Not Live - Work to be initiated | AM34: NOT LIVE - RETAIN BUDGET | AS34: =VLOOKUP(Table8[[#This Row],[CEM Number]],'71 CEMs'!$E$5:$E$76,1,0) -> #N/A | AT34: 46296
A35: I240700 | B35: 45427 | C35: Gujranwala | D35: Gujranwala Ph3 | E35: Ajwa City_P1 | F35: 2202 | G35: 880.8 | M35: =Table8[[#This Row],[Std Remarks]] -> LIVE - 100% Completed | N35: =Table8[[#This Row],[% of Completion of Work Done]] -> 1 | O35: =Table8[[#This Row],[Customers According to % (Market Share)]] -> 880.8 | P35: 60544036 | Q35: =Table8[[#This Row],[Allocated Budget]]*Table8[[#This Row],[Allocation Percentage]] -> 9081605.4 | R35: 51462430 | S35: -1 | U35: 0.4 | V35: 33561.646 | W35: 26265.255 | X35: Buried | Y35: =$Q$2 -> 0.15 | Z35: LIVE | AA35: Buried | AB35: 1 | AC35: =VALUE(SUBSTITUTE(AB35,"%","")) -> 1 | AD35: 46082 | AE35: =IFERROR(Table8[[#This Row],[Timeline - Monthwise]]-MIN(Table8[Start Date..]),"None") -> None | AF35: =IFERROR(Table8[[#This Row],[Timeline - Monthwise]]-Table8[[#This Row],[Start Date..]]+1,"Duration Doesn't Exsists") -> Duration Doesn't Exsists | AG35: =IFERROR(Table8[[#This Row],[Timeline - Monthwise]]-TODAY(),"No ETA") -> No ETA | AH35: =IF(AB35=100%,"Completed",IF(AB35=0%,"Yet to Start","In Progress")) -> Completed | AJ35: Timeline not applicable | AL35: Live - As per Plan | AM35: LIVE - 100% Completed | AS35: =VLOOKUP(Table8[[#This Row],[CEM Number]],'71 CEMs'!$E$5:$E$76,1,0) -> I240700 | AT35: Timeline not applicable
A36: I240700 | B36: 45427 | C36: Gujranwala | D36: Gujranwala Ph3 | E36: Ajwa City_P2 | F36: 3046 | G36: 1218.4 | M36: =Table8[[#This Row],[Std Remarks]] -> NOT LIVE - RETAIN BUDGET | N36: =Table8[[#This Row],[% of Completion of Work Done]] -> 0.75 | O36: =Table8[[#This Row],[Customers According to % (Market Share)]] -> 1218.4 | P36: 74734285 | Q36: =(Table8[[#This Row],[Allocated Budget]]*$Q$2)+(Table8[[#This Row],[Allocated Budget]]*(1-Table8[[#This Row],[HP% based on Live % ( Work Progress)]])*(1-$Q$2)) -> 27091178 | R36: 47643106 | S36: 0 | U36: 0.4 | V36: 41664.379 | W36: 33270.982 | X36: Buried | Y36: =Table8[[#This Row],[% of Completion of Work Done]] -> 0.75 | Z36: NOT LIVE | AB36: 0.75 | AC36: =VALUE(SUBSTITUTE(AB36,"%","")) -> 0.75 | AD36: 46082 | AE36: =IFERROR(Table8[[#This Row],[Timeline - Monthwise]]-MIN(Table8[Start Date..]),"None") -> 31 | AF36: =IFERROR(Table8[[#This Row],[Timeline - Monthwise]]-Table8[[#This Row],[Start Date..]]+1,"Duration Doesn't Exsists") -> 32 | AG36: =IFERROR(Table8[[#This Row],[Timeline - Monthwise]]-TODAY(),"No ETA") -> -16 | AH36: =IF(AB36=100%,"Completed",IF(AB36=0%,"Yet to Start","In Progress")) -> In Progress | AI36: 46113 | AJ36: Apr-2026 | AK36: HHs placement in progress | AL36: Not Live - Work in Progress (WIP) | AM36: NOT LIVE - RETAIN BUDGET | AN36: 1 | AS36: =VLOOKUP(Table8[[#This Row],[CEM Number]],'71 CEMs'!$E$5:$E$76,1,0) -> I240700 | AT36: 46113
A37: I240703 | B37: 45427 | C37: Lahore | D37: Lahore Ph5 | E37: Etihad Town | F37: 2606 | G37: 1042.4 | M37: =Table8[[#This Row],[Std Remarks]] -> LIVE - 100% Completed | N37: =Table8[[#This Row],[% of Completion of Work Done]] -> 1 | O37: =Table8[[#This Row],[Customers According to % (Market Share)]] -> 1042.4 | P37: 35268957 | Q37: =Table8[[#This Row],[Allocated Budget]]*Table8[[#This Row],[Allocation Percentage]] -> 5290343.6 | R37: 29978614 | S37: -1 | U37: 0.4 | V37: 9645 | W37: 5208.75 | X37: Buried | Y37: =$Q$2 -> 0.15 | Z37: LIVE | AA37: Buried | AB37: 1 | AC37: =VALUE(SUBSTITUTE(AB37,"%","")) -> 1 | AD37: 46082 | AE37: =IFERROR(Table8[[#This Row],[Timeline - Monthwise]]-MIN(Table8[Start Date..]),"None") -> None | AF37: =IFERROR(Table8[[#This Row],[Timeline - Monthwise]]-Table8[[#This Row],[Start Date..]]+1,"Duration Doesn't Exsists") -> Duration Doesn't Exsists | AG37: =IFERROR(Table8[[#This Row],[Timeline - Monthwise]]-TODAY(),"No ETA") -> No ETA | AH37: =IF(AB37=100%,"Completed",IF(AB37=0%,"Yet to Start","In Progress")) -> Completed | AJ37: Timeline not applicable | AL37: Live - As per Plan | AM37: LIVE - 100% Completed | AS37: =VLOOKUP(Table8[[#This Row],[CEM Number]],'71 CEMs'!$E$5:$E$76,1,0) -> I240703 | AT37: Timeline not applicable
A38: I240703 | B38: 45427 | C38: Feeders/Transportations | D38: Lahore Ph5 | E38: Feeder | F38: 0 | G38: 0 | M38: =Table8[[#This Row],[Std Remarks]] -> FEEDER ETC WORK - RETAIN BUDGET | N38: =Table8[[#This Row],[% of Completion of Work Done]] -> 0 | O38: =Table8[[#This Row],[Customers According to % (Market Share)]] -> 0 | P38: 82640788 | Q38: =Table8[[#This Row],[Allocated Budget]]*Table8[[#This Row],[Allocation Percentage]] -> 41320394 | R38: 41320394 | S38: -1 | V38: 26448 | W38: 0 | Y38: =$Q$1 -> 0.5 | AB38: 0 | AC38: =VALUE(SUBSTITUTE(AB38,"%","")) -> 0 | AD38: 46082 | AE38: =IFERROR(Table8[[#This Row],[Timeline - Monthwise]]-MIN(Table8[Start Date..]),"None") -> None | AF38: =IFERROR(Table8[[#This Row],[Timeline - Monthwise]]-Table8[[#This Row],[Start Date..]]+1,"Duration Doesn't Exsists") -> Duration Doesn't Exsists | AG38: =IFERROR(Table8[[#This Row],[Timeline - Monthwise]]-TODAY(),"No ETA") -> No ETA | AH38: =IF(AB38=100%,"Completed",IF(AB38=0%,"Yet to Start","In Progress")) -> Yet to Start | AJ38: Timeline not applicable | AL38: Feeders/Trans | AM38: FEEDER ETC WORK - RETAIN BUDGET | AS38: =VLOOKUP(Table8[[#This Row],[CEM Number]],'71 CEMs'!$E$5:$E$76,1,0) -> I240703 | AT38: Timeline not applicable
A39: I240703 | B39: 45427 | C39: Lahore | D39: Lahore Ph5 | E39: Ferozpur Road | F39: 2278 | G39: 911.2 | M39: =Table8[[#This Row],[Std Remarks]] -> NOT LIVE - RETAIN BUDGET | N39: =Table8[[#This Row],[% of Completion of Work Done]] -> 0.1 | O39: =Table8[[#This Row],[Customers According to % (Market Share)]] -> 911.2 | P39: 29293629 | Q39: =(Table8[[#This Row],[Allocated Budget]]*$Q$2)+(Table8[[#This Row],[Allocated Budget]]*(1-Table8[[#This Row],[HP% based on Live % ( Work Progress)]])*(1-$Q$2)) -> 26803670 | R39: 2489958.4 | S39: -1 | U39: 0.4 | V39: 4462 | W39: 11277 | X39: Hybrid | Y39: =Table8[[#This Row],[% of Completion of Work Done]] -> 0.1 | Z39: NOT LIVE | AB39: 0.1 | AC39: =VALUE(SUBSTITUTE(AB39,"%","")) -> 0.1 | AD39: 46082 | AE39: =IFERROR(Table8[[#This Row],[Timeline - Monthwise]]-MIN(Table8[Start Date..]),"None") -> 31 | AF39: =IFERROR(Table8[[#This Row],[Timeline - Monthwise]]-Table8[[#This Row],[Start Date..]]+1,"Duration Doesn't Exsists") -> 32 | AG39: =IFERROR(Table8[[#This Row],[Timeline - Monthwise]]-TODAY(),"No ETA") -> -16 | AH39: =IF(AB39=100%,"Completed",IF(AB39=0%,"Yet to Start","In Progress")) -> In Progress | AI39: 46113 | AJ39: Apr-2026 | AK39: Civil Work hold by TEPA/LDA | AL39: Not Live - Work in Progress (WIP) | AM39: NOT LIVE - RETAIN BUDGET | AN39: 2 | AS39: =VLOOKUP(Table8[[#This Row],[CEM Number]],'71 CEMs'!$E$5:$E$76,1,0) -> I240703 | AT39: 46113
A40: I260599 | B40: No Initiation Date | C40: Dera Ghazi Khan | D40: DG Khan | E40: Ejaz Town | F40: 690 | G40: 310.5 | M40: =Table8[[#This Row],[Std Remarks]] -> NOT LIVE - RETAIN BUDGET | N40: =Table8[[#This Row],[% of Completion of Work Done]] -> 0 | O40: =Table8[[#This Row],[Customers According to % (Market Share)]] -> 310.5 | P40: 8524660.4 | Q40: =(Table8[[#This Row],[Allocated Budget]]*$Q$2)+(Table8[[#This Row],[Allocated Budget]]*(1-Table8[[#This Row],[HP% based on Live % ( Work Progress)]])*(1-$Q$2)) -> 8524660.4 | U40: 0.45 | V40: 2365.55 | W40: 8636.0911 | X40: Hybrid | Y40: =Table8[[#This Row],[% of Completion of Work Done]] -> 0 | Z40: NOT LIVE | AB40: 0 | AC40: =VALUE(SUBSTITUTE(AB40,"%","")) -> 0 | AD40: 46082 | AE40: =IFERROR(Table8[[#This Row],[Timeline - Monthwise]]-MIN(Table8[Start Date..]),"None") -> 214 | AF40: =IFERROR(Table8[[#This Row],[Timeline - Monthwise]]-Table8[[#This Row],[Start Date..]]+1,"Duration Doesn't Exsists") -> 215 | AG40: =IFERROR(Table8[[#This Row],[Timeline - Monthwise]]-TODAY(),"No ETA") -> 167 | AH40: =IF(AB40=100%,"Completed",IF(AB40=0%,"Yet to Start","In Progress")) -> Yet to Start | AI40: 6 Months | AJ40: Oct-2026 | AK40: These Projects have not been started yet, proceedings shall be done post eid | AL40: Not Live - Work to be initiated | AM40: NOT LIVE - RETAIN BUDGET | AS40: =VLOOKUP(Table8[[#This Row],[CEM Number]],'71 CEMs'!$E$5:$E$76,1,0) -> #N/A | AT40: 46296
A41: I260599 | B41: No Initiation Date | C41: Feeders/Transportations | D41: DG Khan | E41: Feeder | F41: 0 | G41: 0 | M41: =Table8[[#This Row],[Std Remarks]] -> FEEDER ETC WORK - RETAIN BUDGET | N41: =Table8[[#This Row],[% of Completion of Work Done]] -> 0 | O41: =Table8[[#This Row],[Customers According to % (Market Share)]] -> 0 | P41: 93527861 | Q41: =Table8[[#This Row],[Allocated Budget]]*Table8[[#This Row],[Allocation Percentage]] -> 93527861 | V41: 30856.1 | W41: 0 | Y41: =$R$1 -> 1 | AB41: 0 | AC41: =VALUE(SUBSTITUTE(AB41,"%","")) -> 0 | AD41: 46082 | AE41: =IFERROR(Table8[[#This Row],[Timeline - Monthwise]]-MIN(Table8[Start Date..]),"None") -> None | AF41: =IFERROR(Table8[[#This Row],[Timeline - Monthwise]]-Table8[[#This Row],[Start Date..]]+1,"Duration Doesn't Exsists") -> Duration Doesn't Exsists | AG41: =IFERROR(Table8[[#This Row],[Timeline - Monthwise]]-TODAY(),"No ETA") -> No ETA | AH41: =IF(AB41=100%,"Completed",IF(AB41=0%,"Yet to Start","In Progress")) -> Yet to Start | AJ41: Timeline not applicable | AL41: Feeders/Trans | AM41: FEEDER ETC WORK - RETAIN BUDGET | AS41: =VLOOKUP(Table8[[#This Row],[CEM Number]],'71 CEMs'!$E$5:$E$76,1,0) -> #N/A | AT41: Timeline not applicable
...

Sheet Sheet1

Sheet KPI 
C4: S.No | D4: Category | E4: KPI Name | F4: What it Tells | G4: Excel Formula (Concept)
C7: 1 | D7: Execution | E7: Total Projects | F7: Overall scale of operations | G7: =Areas!B1 -> 1150
C8: =C7+1 -> 2 | D8: Execution | E8: Live Projects | F8: Revenue-active deployments | G8: ='Live or Not Live'!B4 -> 525
C9: =C8+1 -> 3 | D9: Execution | E9: Not Live Projects | F9: Work completed but not activated | G9: ='Live or Not Live'!B5 -> 625
C10: =C9+1 -> 4 | D10: Execution | E10: Avg Completion % | F10: Overall execution progress | G10: =SUBTOTAL(1,Table8[% of Completion of Work Done]) -> 0.43469046
C11: =C10+1 -> 5 | D11: Execution | E11: Projects ≥80% Complete | F11: Near-finish pipeline | G11: =COUNTIF(Table8[% of Completion of Work Done],">=0.8") -> 579
C12: =C11+1 -> 6 | D12: Financial | E12: Total Allocated Budget | F12: Planned CAPEX | G12: =SUBTOTAL(9,Table8[Allocated Budget]) -> 2.209571e+10
C13: =C12+1 -> 7 | D13: Financial | E13: Total Revised Budget | F13: Updated CAPEX view | G13: =SUBTOTAL(9,Table8[Revised Budget]) -> 1.0815617e+10
C14: =C13+1 -> 8 | D14: Financial | E14: Budget Variance | F14: Over/under spend
C15: =C14+1 -> 9 | D15: Financial | E15: CAPEX at Risk | F15: Money stuck in near-complete, not-live projects
C16: =C15+1 -> 10 | D16: Financial | E16: Cost Efficiency | F16: Spend effectiveness
C17: =C16+1 -> 11 | D17: Risk | E17: Delayed Projects | F17: Execution delays
C18: =C17+1 -> 12 | D18: Risk | E18: Projects Delayed >10 Days | F18: Severe delays
C19: =C18+1 -> 13 | D19: Risk | E19: Near Complete Not Live | F19: Activation bottlenecks
C20: =C19+1 -> 14 | D20: Risk | E20: High CAPEX Not Live | F20: Financial exposure (all stalled)
C21: =C20+1 -> 15 | D21: Risk | E21: Zero Progress Projects | F21: Execution failure / inactivity | G21: =COUNTIF(Table8[% of Completion of Work Done],0) -> 745
C22: =C21+1 -> 16 | D22: Commercial | E22: Total Homes Passed (HP) | F22: Network deployment scale | G22: =SUBTOTAL(9,Table8[Total H.P]) -> 1444140
C23: =C22+1 -> 17 | D23: Commercial | E23: Active Customers | F23: Monetized base | G23: =SUBTOTAL(9,Table8[[Active ]]) -> 13574
C24: =C23+1 -> 18 | D24: Commercial | E24: Conversion % | F24: Deployment → revenue efficiency | G24: =G23/G22 -> 0.0093993657
C25: =C24+1 -> 19 | D25: Commercial | E25: Revenue Potential Blocked | F25: Customers stuck due to non-activation | G25: =SUMIFS(Table8[Total H.P],Table8[Current Status (Live/Not Live)],"Not Live",Table8[% of Completion of Work Done],">=0.8") -> 104840
C26: =C25+1 -> 20 | D26: Commercial | E26: Time to Live | F26: Delay between completion & activation | G26: =AVERAGE(Table8[Start Date..]-Table8[Timeline - Monthwise]) -> -214

Sheet Dashboard - Surface
D1: Approved SF Expansion Feasibilities Report | K1: Total Network | L1: Expected Home Passes | M1: Sellable Capacity | N1: Active Home Passes
J2: Total Network (HP) | K2: ='HP - Customer Network'!B1 -> 1444140 | L2: ='HP - Customer Network'!C1 -> 600881.5
A6: Number of Feasibility | B6: =Feasibilities!B1 -> 97 | D6: Live Areas | E6: =GETPIVOTDATA("Area / Section / Pocket / Society (Original Name)",'Live or Not Live'!$A$3,"Current Status (Live/Not Live)","LIVE") -> 525 | G6: Not Live Areas | H6: =GETPIVOTDATA("Area / Section / Pocket / Society (Original Name)",'Live or Not Live'!$A$3,"Current Status (Live/Not Live)","NOT LIVE") -> 625 | J6: Total Areas | K6: =H6+E6 -> 1150
A10: Live vs Non Live Ratio | G10: Standardized Comment Box | M10: Timeline Box | S10: =_xlfn.AGGREGATE(9,6,Q15:Q38) -> 513
M13: Month | O13: Quarter | Q13: Number of Areas | S13: Quarter - Total
G15: Comments | H15: Count of Areas | M15: 46023 | O15: Q1 | Q15: =IFERROR(VLOOKUP(M15,'Timeline Box'!$F$3:$G$9,2,0)," ") | S15: =SUM(Q15:Q17) -> 37
G16: LIVE - 100% Completed | H16: 512 | M16: 46054 | Q16: =IFERROR(VLOOKUP(M16,'Timeline Box'!$F$4:$G$12,2,0)," ")
G17: LIVE - 25% Completed | H17: 1 | M17: 46082 | Q17: =IFERROR(VLOOKUP(M17,'Timeline Box'!$F$4:$G$12,2,0)," ") -> 37
G18: LIVE - 50% Completed | H18: 6 | M18: 46113 | O18: Q2 | Q18: =IFERROR(VLOOKUP(M18,'Timeline Box'!$F$4:$G$12,2,0)," ") -> 61 | S18: =SUM(Q18:Q20) -> 151
